INFO:     Will watch for changes in these directories: ['/home/workspace']
INFO:     Uvicorn running on http://0.0.0.0:8000 (Press CTRL+C to quit)
INFO:     Started reloader process [5622] using StatReload
Process SpawnProcess-1:
Traceback (most recent call last):
  File "/usr/local/lib/python3.13/multiprocessing/process.py", line 313, in _bootstrap
    self.run()
    ~~~~~~~~^^
  File "/usr/local/lib/python3.13/multiprocessing/process.py", line 108, in run
    self._target(*self._args, **self._kwargs)
    ~~~~~~~~~~~~^^^^^^^^^^^^^^^^^^^^^^^^^^^^^
  File "/usr/local/lib/python3.13/site-packages/uvicorn/_subprocess.py", line 78, in subprocess_started
    target(sockets=sockets)
    ~~~~~~^^^^^^^^^^^^^^^^^
  File "/usr/local/lib/python3.13/site-packages/uvicorn/server.py", line 62, in run
    return asyncio.run(self.serve(sockets=sockets))
           ~~~~~~~~~~~^^^^^^^^^^^^^^^^^^^^^^^^^^^^^
  File "/usr/local/lib/python3.13/asyncio/runners.py", line 195, in run
    return runner.run(main)
           ~~~~~~~~~~^^^^^^
  File "/usr/local/lib/python3.13/asyncio/runners.py", line 118, in run
    return self._loop.run_until_complete(task)
           ~~~~~~~~~~~~~~~~~~~~~~~~~~~~~^^^^^^
  File "/usr/local/lib/python3.13/asyncio/base_events.py", line 725, in run_until_complete
    return future.result()
           ~~~~~~~~~~~~~^^
  File "/usr/local/lib/python3.13/site-packages/uvicorn/server.py", line 69, in serve
    config.load()
    ~~~~~~~~~~~^^
  File "/usr/local/lib/python3.13/site-packages/uvicorn/config.py", line 458, in load
    self.loaded_app = import_from_string(self.app)
                      ~~~~~~~~~~~~~~~~~~^^^^^^^^^^
  File "/usr/local/lib/python3.13/site-packages/uvicorn/importer.py", line 21, in import_from_string
    module = importlib.import_module(module_str)
  File "/usr/local/lib/python3.13/importlib/__init__.py", line 88, in import_module
    return _bootstrap._gcd_import(name[level:], package, level)
           ~~~~~~~~~~~~~~~~~~~~~~^^^^^^^^^^^^^^^^^^^^^^^^^^^^^^
  File "<frozen importlib._bootstrap>", line 1387, in _gcd_import
  File "<frozen importlib._bootstrap>", line 1360, in _find_and_load
  File "<frozen importlib._bootstrap>", line 1331, in _find_and_load_unlocked
  File "<frozen importlib._bootstrap>", line 935, in _load_unlocked
  File "<frozen importlib._bootstrap_external>", line 1026, in exec_module
  File "<frozen importlib._bootstrap>", line 488, in _call_with_frames_removed
  File "/home/workspace/main.py", line 7, in <module>
    from fastapi import FastAPI, HTTPException, Depends, Header
  File "/usr/local/lib/python3.13/site-packages/fastapi/__init__.py", line 7, in <module>
    from .applications import FastAPI as FastAPI
  File "/usr/local/lib/python3.13/site-packages/fastapi/applications.py", line 16, in <module>
    from fastapi import routing
  File "/usr/local/lib/python3.13/site-packages/fastapi/routing.py", line 22, in <module>
    from fastapi import params
  File "/usr/local/lib/python3.13/site-packages/fastapi/params.py", line 5, in <module>
    from fastapi.openapi.models import Example
  File "/usr/local/lib/python3.13/site-packages/fastapi/openapi/models.py", line 170, in <module>
    class Schema(BaseModel):
    ...<91 lines>...
                extra = "allow"
  File "/usr/local/lib/python3.13/site-packages/pydantic/main.py", line 286, in __new__
    cls.__try_update_forward_refs__()
    ~~~~~~~~~~~~~~~~~~~~~~~~~~~~~~~^^
  File "/usr/local/lib/python3.13/site-packages/pydantic/main.py", line 808, in __try_update_forward_refs__
    update_model_forward_refs(cls, cls.__fields__.values(), cls.__config__.json_encoders, localns, (NameError,))
    ~~~~~~~~~~~~~~~~~~~~~~~~~^^^^^^^^^^^^^^^^^^^^^^^^^^^^^^^^^^^^^^^^^^^^^^^^^^^^^^^^^^^^^^^^^^^^^^^^^^^^^^^^^^^
  File "/usr/local/lib/python3.13/site-packages/pydantic/typing.py", line 554, in update_model_forward_refs
    update_field_forward_refs(f, globalns=globalns, localns=localns)
    ~~~~~~~~~~~~~~~~~~~~~~~~~^^^^^^^^^^^^^^^^^^^^^^^^^^^^^^^^^^^^^^^
  File "/usr/local/lib/python3.13/site-packages/pydantic/typing.py", line 520, in update_field_forward_refs
    field.type_ = evaluate_forwardref(field.type_, globalns, localns or None)
                  ~~~~~~~~~~~~~~~~~~~^^^^^^^^^^^^^^^^^^^^^^^^^^^^^^^^^^^^^^^^
  File "/usr/local/lib/python3.13/site-packages/pydantic/typing.py", line 66, in evaluate_forwardref
    return cast(Any, type_)._evaluate(globalns, localns, set())
           ~~~~~~~~~~~~~~~~~~~~~~~~~~^^^^^^^^^^^^^^^^^^^^^^^^^^
TypeError: ForwardRef._evaluate() missing 1 required keyword-only argument: 'recursive_guard'
